<sdf version="1.8">
  <model name="ackermann-vehicle">
    <self_collide>false</self_collide>
    <static>false</static>
    
    <link name="base_link">
      <gz_frame_id>ackermann-vehicle/base_link</gz_frame_id>
      <inertial>
        <pose >0 0 0 0 0 0</pose>
        <mass>3.0</mass>
        <inertia>
          <ixx>0.0054</ixx>
          <ixy>0</ixy>
          <ixz>0</ixz>
          <iyy>0.0252</iyy>
          <iyz>0</iyz>
          <izz>0.0252</izz>
        </inertia>
      </inertial>
      <visual name="BaseVisual">
        <pose>.1371 0 -.0115 -0.018 0 1.5707</pose>
        <geometry>
          <mesh>
           <uri >package://ackermann-vehicle-description/models/ackermann-vehicle/meshes/BaseReduced.dae</uri>
          </mesh>
        </geometry>
      </visual>
      <visual name="ackermann-vehicle/TopVisual">
        <pose>.1371 0 -.0115 -0.018 0 1.5707</pose>
        <geometry>
          <mesh>
          /meshes/BaseReduced.dae
           <uri >package://ackermann-vehicle-description/models/ackermann-vehicle/meshes/TopReduced.dae</uri>
          </mesh>
        </geometry>
      </visual>
      <collision name="ackermann-vehicle/BaseCollision">
        <pose>0 0 .06 0 0 0</pose>
        <geometry>
          <box>
            <size>.3 .09 .12</size>
          </box>
        </geometry>
      </collision>
      <visual name="ackermann-vehicle/visual_lidar">
        <pose>0.05 0 .106 0 0 0</pose> 
        <geometry>
          <mesh>
           <uri >package://ackermann-vehicle-description/models/ackermann-vehicle/meshes/STL27L.dae</uri>
          </mesh>
        </geometry>
      </visual>
      <visual name="ackermann-vehicle/camera_rack">
        <pose>0 0 .184 0 0 0</pose> 
        <geometry>
          <box>
            <size>0.03 0.03 0.03</size>
          </box>
        </geometry>
      </visual>
    </link>

    <link name="front_left_wheel_link">
      <pose relative_to="front_left_wheel_joint">0 0 0 0 0 0</pose>
      <inertial>
        <mass>.05</mass>
        <inertia>
          <ixx>0.00003331</ixx>
          <ixy>0</ixy>
          <ixz>0</ixz>
          <iyy>0.0000204</iyy>
          <iyz>0</iyz>
          <izz>0.0000204</izz>
        </inertia>
      </inertial>
      <gravity>true</gravity>
      <velocity_decay/>
      <visual name="ackermann-vehicle/FrontLeftWheelVisual">
        <pose>0 0 0 0 0 3.14159</pose>
        <geometry>
          <mesh>
           <uri >package://ackermann-vehicle-description/models/ackermann-vehicle/meshes/Wheel.dae</uri>
          </mesh>
        </geometry>
      </visual>
      <collision name="ackermann-vehicle/FrontLeftWheelCollision">
        <pose>0 -.015 0 -1.5707 0 0</pose>
        <geometry>
          <cylinder>
            <length>0.03</length>
            <radius>0.0365</radius>
          </cylinder>
        </geometry>
        <surface>
          <friction>
            <ode>
              <mu>0.5</mu>
              <mu2>1.0</mu2>
              <fdir1>0 0 1</fdir1>
            </ode>
          </friction>
        </surface>
      </collision>
    </link>
    <link name="front_left_wheel_steering_link">
      <pose relative_to="front_left_wheel_steering_joint">0 0 0 0 0 0</pose>
      <inertial>
        <mass>0.005</mass>
        <inertia>
          <ixx>0.0000018</ixx>
          <iyy>0.0000018</iyy>
          <izz>0.0000018</izz>
        </inertia>
      </inertial>
    </link>
    <joint name="front_left_wheel_joint" type="revolute">
      <parent>front_left_wheel_steering_link</parent>
      <child>front_left_wheel_link</child>
      <pose relative_to="front_left_wheel_steering_joint">0 0 0 0 0 0</pose>
      <axis>
        <xyz>0 1 0</xyz>
        <limit>
          <lower>-1.79769e+308</lower>
          <upper>1.79769e+308</upper>
        </limit>
        <dynamics>
          <spring_reference>0</spring_reference>
          <spring_stiffness>0</spring_stiffness>
        </dynamics>
        <use_parent_model_frame>1</use_parent_model_frame>
      </axis>
    </joint>
    <joint name="front_left_wheel_steering_joint" type="revolute">
      <parent>base_link</parent>
      <child>front_left_wheel_steering_link</child>
      <pose relative_to="base_link">.112 .10 0 0 0 0</pose>
      <axis>
        <xyz>0 0 1</xyz>
        <limit>
          <lower>-0.6</lower>
          <upper>0.6</upper>
          <velocity>1.0</velocity>
          <effort>25</effort>
        </limit>
        <use_parent_model_frame>1</use_parent_model_frame>
      </axis>
    </joint>


    <link name="front_right_wheel_link">
      <pose relative_to="front_right_wheel_joint">0 0 0 0 0 0</pose>
      <inertial>
        <mass>.05</mass>
        <inertia>
          <ixx>0.00003331</ixx>
          <ixy>0</ixy>
          <ixz>0</ixz>
          <iyy>0.0000204</iyy>
          <iyz>0</iyz>
          <izz>0.0000204</izz>
        </inertia>
      </inertial>
      <gravity>true</gravity>
      <velocity_decay/>
      <visual name="ackermann-vehicle/FrontRightWheelVisual">
        <pose>0 0 0 0 0 0</pose>
        <geometry>
          <mesh>
           <uri>package://ackermann-vehicle-description/models/ackermann-vehicle/meshes/Wheel.dae</uri>
          </mesh>
        </geometry>
      </visual>
      <collision name="ackermann-vehicle/FrontRightWheelCollision">
        <pose>0 .015 0 -1.5707 0 0</pose>
        <geometry>
          <cylinder>
            <length>0.03</length>
            <radius>0.0365</radius>
          </cylinder>
        </geometry>
        <surface>
          <friction>
            <ode>
              <mu>0.5</mu>
              <mu2>1.0</mu2>
              <fdir1>0 0 1</fdir1>
            </ode>
          </friction>
        </surface>
      </collision>
    </link>
    <link name="front_right_wheel_steering_link">
      <pose relative_to="front_right_wheel_steering_joint">0 0 0 0 0 0</pose>
      <inertial>
        <mass>0.005</mass>
        <inertia>
          <ixx>0.0000018</ixx>
          <iyy>0.0000018</iyy>
          <izz>0.0000018</izz>
        </inertia>
      </inertial>
    </link>
    <joint name="front_right_wheel_joint" type="revolute">
      <parent>front_right_wheel_steering_link</parent>
      <child>front_right_wheel_link</child>
      <pose relative_to="front_right_wheel_steering_joint">0 0 0 0 0 0</pose>
      <axis>
        <xyz>0 1 0</xyz>
        <limit>
          <lower>-1.79769e+308</lower>
          <upper>1.79769e+308</upper>
        </limit>
        <dynamics>
          <spring_reference>0</spring_reference>
          <spring_stiffness>0</spring_stiffness>
        </dynamics>
        <use_parent_model_frame>1</use_parent_model_frame>
      </axis>
    </joint>
    <joint name="front_right_wheel_steering_joint" type="revolute">
      <parent>base_link</parent>
      <child>front_right_wheel_steering_link</child>
      <pose relative_to="base_link">.112 -.10 0 0 0 0</pose>
      <axis>
        <xyz>0 0 1</xyz>
        <limit>
          <lower>-0.6</lower>
          <upper>0.6</upper>
          <velocity>1.0</velocity>
          <effort>25</effort>
        </limit>
        <use_parent_model_frame>1</use_parent_model_frame>
      </axis>
    </joint>


    <joint name="rear_right_wheel_joint" type="revolute">
      <parent>base_link</parent>
      <child>rear_right_wheel_link</child>
      <pose relative_to="base_link">-.1135 -.10 0 0 0 0</pose>
      <axis>
        <xyz>0 1 0</xyz>
        <limit>
          <lower>-1.79769e+308</lower>
          <upper>1.79769e+308</upper>
        </limit>
        <dynamics>
          <spring_reference>0</spring_reference>
          <spring_stiffness>0</spring_stiffness>
        </dynamics>
        <use_parent_model_frame>1</use_parent_model_frame>
      </axis>
    </joint>
    <joint name="rear_left_wheel_joint" type="revolute">
      <parent>base_link</parent>
      <child>rear_left_wheel_link</child>
      <pose relative_to="base_link">-.1135 .10 0 0 0 0</pose>
      <axis>
        <xyz>0 1 0</xyz>
        <limit>
          <lower>-1.79769e+308</lower>
          <upper>1.79769e+308</upper>
        </limit>
        <dynamics>
          <spring_reference>0</spring_reference>
          <spring_stiffness>0</spring_stiffness>
        </dynamics>
        <use_parent_model_frame>1</use_parent_model_frame>
      </axis>
    </joint>
    <link name="rear_right_wheel_link">
      <pose relative_to="rear_right_wheel_joint">0 0 0 0 0 0</pose>
      <inertial>
        <mass>.05</mass>
        <inertia>
          <ixx>0.00003331</ixx>
          <ixy>0</ixy>
          <ixz>0</ixz>
          <iyy>0.0000204</iyy>
          <iyz>0</iyz>
          <izz>0.0000204</izz>
        </inertia>
      </inertial>
      <gravity>true</gravity>
      <velocity_decay/>
      <visual name="RearRightWheelVisual">
        <pose>0 0 0 0 0 0</pose>
        <geometry>
          <mesh>
           <uri >package://ackermann-vehicle-description/models/ackermann-vehicle/meshes/Wheel.dae</uri>
          </mesh>
        </geometry>
      </visual>
      <collision name="RearRightWheelCollision">
        <pose>0 .015 0 -1.5707 0 0</pose>
        <geometry>
          <cylinder>
            <length>0.03</length>
            <radius>0.0365</radius>
          </cylinder>
        </geometry>
        <surface>
          <friction>
            <ode>
              <mu>0.5</mu>
              <mu2>1.0</mu2>
              <fdir1>0 0 1</fdir1>
            </ode>
          </friction>
        </surface>
      </collision>
    </link>
    <link name="rear_left_wheel_link">
      <pose relative_to="rear_left_wheel_joint">0 0 0 0 0 0</pose>
      <inertial>
        <mass>.05</mass>
        <inertia>
          <ixx>0.00003331</ixx>
          <ixy>0</ixy>
          <ixz>0</ixz>
          <iyy>0.0000204</iyy>
          <iyz>0</iyz>
          <izz>0.0000204</izz>
        </inertia>
      </inertial>
      <gravity>true</gravity>
      <velocity_decay/>
      <visual name="RearLeftWheelVisual">
        <pose>0 0 0 0 0 3.14159</pose>
        <geometry>
          <mesh>
           <uri >package://ackermann-vehicle-description/models/ackermann-vehicle/meshes/Wheel.dae</uri>
          </mesh>
        </geometry>
      </visual>
      <collision name="RearLeftWheelCollision">
        <pose>0 -.015 0 -1.5707 0 0</pose>
        <geometry>
          <cylinder>
            <length>0.03</length>
            <radius>0.0365</radius>
          </cylinder>
        </geometry>
        <surface>
          <friction>
            <ode>
              <mu>0.5</mu>
              <mu2>1.0</mu2>
              <fdir1>0 0 1</fdir1>
            </ode>
          </friction>
        </surface>
      </collision>
    </link>

    <plugin
      filename="gz-sim-ackermann-steering-system"
      name="gz::sim::systems::AckermannSteering">
      <left_joint>front_left_wheel_joint</left_joint>
      <left_joint>rear_left_wheel_joint</left_joint>
      <right_joint>front_right_wheel_joint</right_joint>
      <right_joint>front_right_wheel_joint</right_joint>
      <left_steering_joint>front_left_wheel_steering_joint</left_steering_joint>
      <right_steering_joint>front_right_wheel_steering_joint</right_steering_joint>
      <kingpin_width>0.199</kingpin_width>
      <steering_limit>0.4</steering_limit>
      <wheel_base>.2255</wheel_base>
      <wheel_separation>.2</wheel_separation>
      <wheel_radius>0.0365</wheel_radius>
      <min_velocity>-10.0</min_velocity>
      <max_velocity>10.0</max_velocity>
      <min_acceleration>-10</min_acceleration>
      <max_acceleration>10</max_acceleration>
      <topic>/cmd_vel</topic>
    </plugin>

    <plugin
      filename="gz-sim-pose-publisher-system"
      name="gz::sim::systems::PosePublisher">
      <publish_link_pose>true</publish_link_pose>
      <publish_sensor_pose>true</publish_sensor_pose>
      <publish_model_pose>false</publish_model_pose>
      <use_pose_vector_msg>true</use_pose_vector_msg>
    </plugin>

    <plugin
      filename="gz-sim-odometry-publisher-system"
      name="gz::sim::systems::OdometryPublisher">
      <odom_frame>odom</odom_frame>
      <robot_base_frame>ackermann-vehicle</robot_base_frame>
      <odom_topic>odom</odom_topic> 
      <dimensions>3</dimensions>
    </plugin>

    <plugin
      filename="gz-sim-joint-state-publisher-system"
      name="gz::sim::systems::JointStatePublisher">
    </plugin> 

  </model>
</sdf>
